Workbook
Name Slicer_Category: #N/A
Name Slicer_month_name: #N/A
Name Slicer_State: #N/A
Name Slicer_years: #N/A

Sheet Dashboard
J2: Sales Report Years | K2: =IF('Pivot Table'!P5=1,'Pivot Table'!N4,"All") -> All | N2: Total Profit | Q2: Total Sales
N3: =GETPIVOTDATA("Profit",'Pivot Table'!$L$3) -> 18746.179 | Q3: =GETPIVOTDATA("Amount",'Pivot Table'!$J$3) -> 977995.9

Sheet Table
G2: State | H2: Sum of Amount | L2: Sales Report Years | M2: =IF('Pivot Table'!P5=1,'Pivot Table'!N4,"All") -> All
G3: Alabama | H3: 5271.88
G4: Arizona | H4: 28059.676
G5: Arkansas | H5: 223.32 | J5: Region | K5: Sum of Amount
G6: California | H6: 198392.4 | J6: Central | K6: 282285.91
G7: Colorado | H7: 22720.554 | J7: East | K7: 225924.14
G8: Connecticut | H8: 5164.25 | J8: South | K8: 157876.67
G9: Delaware | H9: 3333.78 | J9: West | K9: 311909.18
G10: Florida | H10: 23721.861 | J10: Grand Total | K10: 977995.9
G11: Georgia | H11: 38382.84
G12: Illinois | H12: 38843.495 | M12: Top 5 Products | N12: Sum of Amount
G13: Indiana | H13: 1983.27 | J13: Ship Mode | K13: Sum of Amount | M13: Fellowes PB300 Plastic Comb Binding Machine | N13: 19011.51
G14: Iowa | H14: 1465.04 | J14: First Class | K14: 132970.29 | M14: Fellowes PB500 Electric Punch Plastic Comb Binding Machine with Manual Bind | N14: 31774.75
G15: Kentucky | H15: 8826.55 | J15: Same Day | K15: 44029.373 | M15: Hon Deluxe Fabric Upholstered Stacking Chairs, Rounded Back | N15: 17810.54
G16: Louisiana | H16: 10357.89 | J16: Second Class | K16: 173132.41 | M16: Lexmark MX611dhe Monochrome Laser Printer | N16: 50183.705
G17: Maryland | H17: 263.62 | J17: Standard Class | K17: 627863.83 | M17: Logitech P710e Mobile Speakerphone | N17: 44998.952
G18: Massachusetts | H18: 11397.838 | J18: Grand Total | K18: 977995.9 | M18: Grand Total | N18: 163779.46
G19: Michigan | H19: 55658.633
G20: Minnesota | H20: 24378.16
G21: Mississippi | H21: 6977.35 | J21: Top 10 Customers | K21: Sum of Amount
G22: Missouri | H22: 2973.27 | J22: Alan Dominguez | K22: 19817.252
G23: Montana | H23: 18556.08 | J23: Becky Martin | K23: 51493.651
G24: Nebraska | H24: 1065.31 | J24: Brosina Hoffman | K24: 20545.461
G25: Nevada | H25: 181.9008 | J25: Christopher Martinez | K25: 31942.73
G26: New Hampshire | H26: 2216.99 | J26: Dianna Wilson | K26: 22253.67
G27: New Jersey | H27: 13211.13 | J27: Justin Ellison | K27: 21151.33
G28: New Mexico | H28: 301.99 | J28: Keith Herrera | K28: 24812.456
G29: New York | H29: 107723.31 | J29: Kelly Collister | K29: 43770.754
G30: North Carolina | H30: 28898.376 | J30: Mitch Willingham | K30: 20865.42
G31: Ohio | H31: 19159.156 | J31: Ross Baird | K31: 26334.514
G32: Oklahoma | H32: 6899.27 | J32: Grand Total | K32: 282987.24
G33: Oregon | H33: 1911.6291
G34: Pennsylvania | H34: 63328.234
G35: Rhode Island | H35: 125.84
G36: South Carolina | H36: 1163.99
G37: Tennessee | H37: 8904.7674
G38: Texas | H38: 119213.34
G39: Utah | H39: 3848.1892
G40: Virginia | H40: 25147.85
G41: Washington | H41: 37936.754
...

Sheet Pivot Table
A3: Row Labels | B3: Sum of Amount | D3: Row Labels | E3: Sum of Amount | G3: Row Labels | H3: Sum of Amount | J3: Sum of Amount | L3: Sum of Profit | N3: Row Labels
A4: Central | B4: 282285.91 | D4: First Class | E4: 132970.29 | G4: Alan Dominguez | H4: 19817.252 | J4: 977995.9 | L4: 18746.179 | N4: 2016 | P4: Quition
A5: East | B5: 225924.14 | D5: Same Day | E5: 44029.373 | G5: Becky Martin | H5: 51493.651 | N5: 2017 | P5: =COUNT($N$4:$N$7) -> 4
A6: South | B6: 157876.67 | D6: Second Class | E6: 173132.41 | G6: Brosina Hoffman | H6: 20545.461 | N6: 2018
A7: West | B7: 311909.18 | D7: Standard Class | E7: 627863.83 | G7: Christopher Martinez | H7: 31942.73 | N7: 2019
A8: Grand Total | B8: 977995.9 | D8: Grand Total | E8: 977995.9 | G8: Dianna Wilson | H8: 22253.67 | N8: Grand Total
G9: Justin Ellison | H9: 21151.33
G10: Keith Herrera | H10: 24812.456
G11: Kelly Collister | H11: 43770.754
G12: Mitch Willingham | H12: 20865.42
G13: Ross Baird | H13: 26334.514 | N13: Row Labels | O13: Sum of Amount
G14: Grand Total | H14: 282987.24 | N14: Fellowes PB300 Plastic Comb Binding Machine | O14: 19011.51
N15: Fellowes PB500 Electric Punch Plastic Comb Binding Machine with Manual Bind | O15: 31774.75
N16: Hon Deluxe Fabric Upholstered Stacking Chairs, Rounded Back | O16: 17810.54
N17: Lexmark MX611dhe Monochrome Laser Printer | O17: 50183.705
N18: Logitech P710e Mobile Speakerphone | O18: 44998.952
N19: Grand Total | O19: 163779.46
A20: Row Labels | B20: Sum of Amount | D20: Row Labels | E20: Sum of Amount
A21: Alabama | B21: 5271.88 | D21: Alabama | E21: 5271.88
A22: Arizona | B22: 28059.676 | D22: Arizona | E22: 28059.676
A23: Arkansas | B23: 223.32 | D23: Arkansas | E23: 223.32
A24: California | B24: 198392.4 | D24: California | E24: 198392.4
A25: Colorado | B25: 22720.554 | D25: Colorado | E25: 22720.554
A26: Connecticut | B26: 5164.25 | D26: Connecticut | E26: 5164.25
A27: Delaware | B27: 3333.78 | D27: Delaware | E27: 3333.78
A28: Florida | B28: 23721.861 | D28: Florida | E28: 23721.861
A29: Georgia | B29: 38382.84 | D29: Georgia | E29: 38382.84
A30: Illinois | B30: 38843.495 | D30: Illinois | E30: 38843.495
A31: Indiana | B31: 1983.27 | D31: Indiana | E31: 1983.27
A32: Iowa | B32: 1465.04 | D32: Iowa | E32: 1465.04
... A60: Wisconsin | B60: 29806.12 | D60: Wisconsin | E60: 29806.12

Sheet Work File (2)
A1: Row ID | B1: Order ID | C1: Order Date | D1: Ship Mode | E1: Customer Name | F1: City | G1: State | H1: Region | I1: Category | J1: Sub-Category | K1: Product Name | L1: Sales | M1: Quantity | N1: Discount | O1: Profit | P1: Amount | Q1: years | R1: month name | S1: status
A2: 1 | B2: CA-2018-152156 | C2: 43412 | D2: Second Class | E2: Claire Gute | F2: Henderson | G2: Kentucky | H2: South | I2: Furniture | J2: Bookcases | K2: Bush Somerset Collection Bookcase | L2: 261.96 | M2: 2 | N2: 0 | O2: 41.9136 | P2: =('Work File (2)'!$L2*'Work File (2)'!$M2)*(1-'Work File (2)'!$N2) -> 523.92 | Q2: =YEAR(Table2[[#This Row],[Order Date]]) -> 2018 | R2: =TEXT(Table2[[#This Row],[Order Date]],"mmm") -> Nov
A3: 2 | B3: CA-2018-152156 | C3: 43412 | D3: Second Class | E3: Claire Gute | F3: Henderson | G3: Kentucky | H3: South | I3: Furniture | J3: Chairs | K3: Hon Deluxe Fabric Upholstered Stacking Chairs, Rounded Back | L3: 731.94 | M3: 3 | N3: 0 | O3: 219.582 | P3: =('Work File (2)'!$L3*'Work File (2)'!$M3)*(1-'Work File (2)'!$N3) -> 2195.82 | Q3: =YEAR(Table2[[#This Row],[Order Date]]) -> 2018 | R3: =TEXT(Table2[[#This Row],[Order Date]],"mmm") -> Nov
A4: 3 | B4: CA-2018-138688 | C4: 43263 | D4: Second Class | E4: Darrin Van Huff | F4: Los Angeles | G4: California | H4: West | I4: Office Supplies | J4: Labels | K4: Self-Adhesive Address Labels for Typewriters by Universal | L4: 14.62 | M4: 2 | N4: 0 | O4: 6.8714 | P4: =('Work File (2)'!$L4*'Work File (2)'!$M4)*(1-'Work File (2)'!$N4) -> 29.24 | Q4: =YEAR(Table2[[#This Row],[Order Date]]) -> 2018 | R4: =TEXT(Table2[[#This Row],[Order Date]],"mmm") -> Jun
A5: 4 | B5: US-2017-108966 | C5: 43019 | D5: Standard Class | E5: Sean O'Donnell | F5: Fort Lauderdale | G5: Florida | H5: South | I5: Furniture | J5: Tables | K5: Bretford CR4500 Series Slim Rectangular Table | L5: 957.5775 | M5: 5 | N5: 0.45 | O5: -383.031 | P5: =('Work File (2)'!$L5*'Work File (2)'!$M5)*(1-'Work File (2)'!$N5) -> 2633.3381 | Q5: =YEAR(Table2[[#This Row],[Order Date]]) -> 2017 | R5: =TEXT(Table2[[#This Row],[Order Date]],"mmm") -> Oct
A6: 5 | B6: US-2017-108966 | C6: 43019 | D6: Standard Class | E6: Sean O'Donnell | F6: Fort Lauderdale | G6: Florida | H6: South | I6: Office Supplies | J6: Storage | K6: Eldon Fold 'N Roll Cart System | L6: 22.368 | M6: 2 | N6: 0.2 | O6: 2.5164 | P6: =('Work File (2)'!$L6*'Work File (2)'!$M6)*(1-'Work File (2)'!$N6) -> 35.7888 | Q6: =YEAR(Table2[[#This Row],[Order Date]]) -> 2017 | R6: =TEXT(Table2[[#This Row],[Order Date]],"mmm") -> Oct
A7: 6 | B7: CA-2016-115812 | C7: 42530 | D7: Standard Class | E7: Brosina Hoffman | F7: Los Angeles | G7: California | H7: West | I7: Furniture | J7: Furnishings | K7: Eldon Expressions Wood and Plastic Desk Accessories, Cherry Wood | L7: 48.86 | M7: 7 | N7: 0 | O7: 14.1694 | P7: =('Work File (2)'!$L7*'Work File (2)'!$M7)*(1-'Work File (2)'!$N7) -> 342.02 | Q7: =YEAR(Table2[[#This Row],[Order Date]]) -> 2016 | R7: =TEXT(Table2[[#This Row],[Order Date]],"mmm") -> Jun
A8: 7 | B8: CA-2016-115812 | C8: 42530 | D8: Standard Class | E8: Brosina Hoffman | F8: Los Angeles | G8: California | H8: West | I8: Office Supplies | J8: Art | K8: Newell 322 | L8: 7.28 | M8: 4 | N8: 0 | O8: 1.9656 | P8: =('Work File (2)'!$L8*'Work File (2)'!$M8)*(1-'Work File (2)'!$N8) -> 29.12 | Q8: =YEAR(Table2[[#This Row],[Order Date]]) -> 2016 | R8: =TEXT(Table2[[#This Row],[Order Date]],"mmm") -> Jun
A9: 8 | B9: CA-2016-115812 | C9: 42530 | D9: Standard Class | E9: Brosina Hoffman | F9: Los Angeles | G9: California | H9: West | I9: Technology | J9: Phones | K9: Mitel 5320 IP Phone VoIP phone | L9: 907.152 | M9: 6 | N9: 0.2 | O9: 90.7152 | P9: =('Work File (2)'!$L9*'Work File (2)'!$M9)*(1-'Work File (2)'!$N9) -> 4354.3296 | Q9: =YEAR(Table2[[#This Row],[Order Date]]) -> 2016 | R9: =TEXT(Table2[[#This Row],[Order Date]],"mmm") -> Jun
A10: 9 | B10: CA-2016-115812 | C10: 42530 | D10: Standard Class | E10: Brosina Hoffman | F10: Los Angeles | G10: California | H10: West | I10: Office Supplies | J10: Binders | K10: DXL Angle-View Binders with Locking Rings by Samsill | L10: 18.504 | M10: 3 | N10: 0.2 | O10: 5.7825 | P10: =('Work File (2)'!$L10*'Work File (2)'!$M10)*(1-'Work File (2)'!$N10) -> 44.4096 | Q10: =YEAR(Table2[[#This Row],[Order Date]]) -> 2016 | R10: =TEXT(Table2[[#This Row],[Order Date]],"mmm") -> Jun
A11: 10 | B11: CA-2016-115812 | C11: 42530 | D11: Standard Class | E11: Brosina Hoffman | F11: Los Angeles | G11: California | H11: West | I11: Office Supplies | J11: Appliances | K11: Belkin F5C206VTEL 6 Outlet Surge | L11: 114.9 | M11: 5 | N11: 0 | O11: 34.47 | P11: =('Work File (2)'!$L11*'Work File (2)'!$M11)*(1-'Work File (2)'!$N11) -> 574.5 | Q11: =YEAR(Table2[[#This Row],[Order Date]]) -> 2016 | R11: =TEXT(Table2[[#This Row],[Order Date]],"mmm") -> Jun
A12: 11 | B12: CA-2016-115812 | C12: 42530 | D12: Standard Class | E12: Brosina Hoffman | F12: Los Angeles | G12: California | H12: West | I12: Furniture | J12: Tables | K12: Chromcraft Rectangular Conference Tables | L12: 1706.184 | M12: 9 | N12: 0.2 | O12: 85.3092 | P12: =('Work File (2)'!$L12*'Work File (2)'!$M12)*(1-'Work File (2)'!$N12) -> 12284.525 | Q12: =YEAR(Table2[[#This Row],[Order Date]]) -> 2016 | R12: =TEXT(Table2[[#This Row],[Order Date]],"mmm") -> Jun
A13: 12 | B13: CA-2016-115812 | C13: 42530 | D13: Standard Class | E13: Brosina Hoffman | F13: Los Angeles | G13: California | H13: West | I13: Technology | J13: Phones | K13: Konftel 250 Conference phone - Charcoal black | L13: 911.424 | M13: 4 | N13: 0.2 | O13: 68.3568 | P13: =('Work File (2)'!$L13*'Work File (2)'!$M13)*(1-'Work File (2)'!$N13) -> 2916.5568 | Q13: =YEAR(Table2[[#This Row],[Order Date]]) -> 2016 | R13: =TEXT(Table2[[#This Row],[Order Date]],"mmm") -> Jun
... A1001: 1000 | B1001: CA-2017-162537 | C1001: 43036 | D1001: Standard Class | E1001: Rob Dowd | F1001: Henderson | G1001: Kentucky | H1001: South | I1001: Furniture | J1001: Furnishings | K1001: C-Line Cubicle Keepers Polyproplyene Holder With Velcro Backings | L1001: 33.11 | M1001: 7 | N1001: 0 | O1001: 12.9129 | P1001: =('Work File (2)'!$L1001*'Work File (2)'!$M1001)*(1-'Work File (2)'!$N1001) -> 231.77 | Q1001: =YEAR(Table2[[#This Row],[Order Date]]) -> 2017 | R1001: =TEXT(Table2[[#This Row],[Order Date]],"mmm") -> Oct
